[2025-09-21 20:54:45,556] ERROR core.views Test error log from shell
[2025-09-21 21:18:43,753] ERROR django.request Internal Server Error: /customers/
Traceback (most recent call last):
  File "C:\Users\paxto\Desktop\My Web Sites\tucker_and_dales_home_services\.venv\Lib\site-packages\django\template\backends\django.py", line 61, in render
    return self.template.render(context)
           ^^^^^^^^^^^^^^^^^^^^^^^^^^^^^
  File "C:\Users\paxto\Desktop\My Web Sites\tucker_and_dales_home_services\.venv\Lib\site-packages\django\template\base.py", line 175, in render
    return self._render(context)
           ^^^^^^^^^^^^^^^^^^^^^
  File "C:\Users\paxto\Desktop\My Web Sites\tucker_and_dales_home_services\.venv\Lib\site-packages\django\template\base.py", line 167, in _render
    return self.nodelist.render(context)
           ^^^^^^^^^^^^^^^^^^^^^^^^^^^^^
  File "C:\Users\paxto\Desktop\My Web Sites\tucker_and_dales_home_services\.venv\Lib\site-packages\django\template\base.py", line 1005, in render
    return SafeString("".join([node.render_annotated(context) for node in self]))
                               ^^^^^^^^^^^^^^^^^^^^^^^^^^^^^^
  File "C:\Users\paxto\Desktop\My Web Sites\tucker_and_dales_home_services\.venv\Lib\site-packages\django\template\base.py", line 966, in render_annotated
    return self.render(context)
           ^^^^^^^^^^^^^^^^^^^^
  File "C:\Users\paxto\Desktop\My Web Sites\tucker_and_dales_home_services\.venv\Lib\site-packages\django\template\loader_tags.py", line 132, in render
    compiled_parent = self.get_parent(context)
                      ^^^^^^^^^^^^^^^^^^^^^^^^
  File "C:\Users\paxto\Desktop\My Web Sites\tucker_and_dales_home_services\.venv\Lib\site-packages\django\template\loader_tags.py", line 129, in get_parent
    return self.find_template(parent, context)
           ^^^^^^^^^^^^^^^^^^^^^^^^^^^^^^^^^^^
  File "C:\Users\paxto\Desktop\My Web Sites\tucker_and_dales_home_services\.venv\Lib\site-packages\django\template\loader_tags.py", line 107, in find_template
    template, origin = context.template.engine.find_template(
                       ^^^^^^^^^^^^^^^^^^^^^^^^^^^^^^^^^^^^^^
  File "C:\Users\paxto\Desktop\My Web Sites\tucker_and_dales_home_services\.venv\Lib\site-packages\django\template\engine.py", line 161, in find_template
    raise TemplateDoesNotExist(name, tried=tried)
django.template.exceptions.TemplateDoesNotExist: base.html

The above exception was the direct cause of the following exception:

Traceback (most recent call last):
  File "C:\Users\paxto\Desktop\My Web Sites\tucker_and_dales_home_services\.venv\Lib\site-packages\django\core\handlers\exception.py", line 55, in inner
    response = get_response(request)
               ^^^^^^^^^^^^^^^^^^^^^
  File "C:\Users\paxto\Desktop\My Web Sites\tucker_and_dales_home_services\.venv\Lib\site-packages\django\core\handlers\base.py", line 197, in _get_response
    response = wrapped_callback(request, *callback_args, **callback_kwargs)
               ^^^^^^^^^^^^^^^^^^^^^^^^^^^^^^^^^^^^^^^^^^^^^^^^^^^^^^^^^^^^
  File "C:\Users\paxto\Desktop\My Web Sites\tucker_and_dales_home_services\customers\views.py", line 13, in customer_list
    return render(request, "customers/customer_list.html", {"customers": customers})
           ^^^^^^^^^^^^^^^^^^^^^^^^^^^^^^^^^^^^^^^^^^^^^^^^^^^^^^^^^^^^^^^^^^^^^^^^^
  File "C:\Users\paxto\Desktop\My Web Sites\tucker_and_dales_home_services\.venv\Lib\site-packages\django\shortcuts.py", line 24, in render
    content = loader.render_to_string(template_name, context, request, using=using)
              ^^^^^^^^^^^^^^^^^^^^^^^^^^^^^^^^^^^^^^^^^^^^^^^^^^^^^^^^^^^^^^^^^^^^^
  File "C:\Users\paxto\Desktop\My Web Sites\tucker_and_dales_home_services\.venv\Lib\site-packages\django\template\loader.py", line 62, in render_to_string
    return template.render(context, request)
           ^^^^^^^^^^^^^^^^^^^^^^^^^^^^^^^^^
  File "C:\Users\paxto\Desktop\My Web Sites\tucker_and_dales_home_services\.venv\Lib\site-packages\django\template\backends\django.py", line 63, in render
    reraise(exc, self.backend)
  File "C:\Users\paxto\Desktop\My Web Sites\tucker_and_dales_home_services\.venv\Lib\site-packages\django\template\backends\django.py", line 84, in reraise
    raise new from exc
django.template.exceptions.TemplateDoesNotExist: base.html
[2025-09-21 21:18:43,760] ERROR django.server "GET /customers/ HTTP/1.1" 500 145875
[2025-09-21 21:24:13,030] ERROR django.request Internal Server Error: /customers/
Traceback (most recent call last):
  File "C:\Users\paxto\Desktop\My Web Sites\tucker_and_dales_home_services\.venv\Lib\site-packages\django\template\backends\django.py", line 61, in render
    return self.template.render(context)
           ^^^^^^^^^^^^^^^^^^^^^^^^^^^^^
  File "C:\Users\paxto\Desktop\My Web Sites\tucker_and_dales_home_services\.venv\Lib\site-packages\django\template\base.py", line 175, in render
    return self._render(context)
           ^^^^^^^^^^^^^^^^^^^^^
  File "C:\Users\paxto\Desktop\My Web Sites\tucker_and_dales_home_services\.venv\Lib\site-packages\django\template\base.py", line 167, in _render
    return self.nodelist.render(context)
           ^^^^^^^^^^^^^^^^^^^^^^^^^^^^^
  File "C:\Users\paxto\Desktop\My Web Sites\tucker_and_dales_home_services\.venv\Lib\site-packages\django\template\base.py", line 1005, in render
    return SafeString("".join([node.render_annotated(context) for node in self]))
                               ^^^^^^^^^^^^^^^^^^^^^^^^^^^^^^
  File "C:\Users\paxto\Desktop\My Web Sites\tucker_and_dales_home_services\.venv\Lib\site-packages\django\template\base.py", line 966, in render_annotated
    return self.render(context)
           ^^^^^^^^^^^^^^^^^^^^
  File "C:\Users\paxto\Desktop\My Web Sites\tucker_and_dales_home_services\.venv\Lib\site-packages\django\template\loader_tags.py", line 132, in render
    compiled_parent = self.get_parent(context)
                      ^^^^^^^^^^^^^^^^^^^^^^^^
  File "C:\Users\paxto\Desktop\My Web Sites\tucker_and_dales_home_services\.venv\Lib\site-packages\django\template\loader_tags.py", line 129, in get_parent
    return self.find_template(parent, context)
           ^^^^^^^^^^^^^^^^^^^^^^^^^^^^^^^^^^^
  File "C:\Users\paxto\Desktop\My Web Sites\tucker_and_dales_home_services\.venv\Lib\site-packages\django\template\loader_tags.py", line 107, in find_template
    template, origin = context.template.engine.find_template(
                       ^^^^^^^^^^^^^^^^^^^^^^^^^^^^^^^^^^^^^^
  File "C:\Users\paxto\Desktop\My Web Sites\tucker_and_dales_home_services\.venv\Lib\site-packages\django\template\engine.py", line 161, in find_template
    raise TemplateDoesNotExist(name, tried=tried)
django.template.exceptions.TemplateDoesNotExist: base.html

The above exception was the direct cause of the following exception:

Traceback (most recent call last):
  File "C:\Users\paxto\Desktop\My Web Sites\tucker_and_dales_home_services\.venv\Lib\site-packages\django\core\handlers\exception.py", line 55, in inner
    response = get_response(request)
               ^^^^^^^^^^^^^^^^^^^^^
  File "C:\Users\paxto\Desktop\My Web Sites\tucker_and_dales_home_services\.venv\Lib\site-packages\django\core\handlers\base.py", line 197, in _get_response
    response = wrapped_callback(request, *callback_args, **callback_kwargs)
               ^^^^^^^^^^^^^^^^^^^^^^^^^^^^^^^^^^^^^^^^^^^^^^^^^^^^^^^^^^^^
  File "C:\Users\paxto\Desktop\My Web Sites\tucker_and_dales_home_services\customers\views.py", line 13, in customer_list
    return render(request, "customers/customer_list.html", {"customers": customers})
           ^^^^^^^^^^^^^^^^^^^^^^^^^^^^^^^^^^^^^^^^^^^^^^^^^^^^^^^^^^^^^^^^^^^^^^^^^
  File "C:\Users\paxto\Desktop\My Web Sites\tucker_and_dales_home_services\.venv\Lib\site-packages\django\shortcuts.py", line 24, in render
    content = loader.render_to_string(template_name, context, request, using=using)
              ^^^^^^^^^^^^^^^^^^^^^^^^^^^^^^^^^^^^^^^^^^^^^^^^^^^^^^^^^^^^^^^^^^^^^
  File "C:\Users\paxto\Desktop\My Web Sites\tucker_and_dales_home_services\.venv\Lib\site-packages\django\template\loader.py", line 62, in render_to_string
    return template.render(context, request)
           ^^^^^^^^^^^^^^^^^^^^^^^^^^^^^^^^^
  File "C:\Users\paxto\Desktop\My Web Sites\tucker_and_dales_home_services\.venv\Lib\site-packages\django\template\backends\django.py", line 63, in render
    reraise(exc, self.backend)
  File "C:\Users\paxto\Desktop\My Web Sites\tucker_and_dales_home_services\.venv\Lib\site-packages\django\template\backends\django.py", line 84, in reraise
    raise new from exc
django.template.exceptions.TemplateDoesNotExist: base.html
[2025-09-21 21:24:13,036] ERROR django.server "GET /customers/ HTTP/1.1" 500 147043
[2025-09-21 21:24:34,159] ERROR django.request Internal Server Error: /
Traceback (most recent call last):
  File "C:\Users\paxto\Desktop\My Web Sites\tucker_and_dales_home_services\.venv\Lib\site-packages\django\template\backends\django.py", line 61, in render
    return self.template.render(context)
           ^^^^^^^^^^^^^^^^^^^^^^^^^^^^^
  File "C:\Users\paxto\Desktop\My Web Sites\tucker_and_dales_home_services\.venv\Lib\site-packages\django\template\base.py", line 175, in render
    return self._render(context)
           ^^^^^^^^^^^^^^^^^^^^^
  File "C:\Users\paxto\Desktop\My Web Sites\tucker_and_dales_home_services\.venv\Lib\site-packages\django\template\base.py", line 167, in _render
    return self.nodelist.render(context)
           ^^^^^^^^^^^^^^^^^^^^^^^^^^^^^
  File "C:\Users\paxto\Desktop\My Web Sites\tucker_and_dales_home_services\.venv\Lib\site-packages\django\template\base.py", line 1005, in render
    return SafeString("".join([node.render_annotated(context) for node in self]))
                               ^^^^^^^^^^^^^^^^^^^^^^^^^^^^^^
  File "C:\Users\paxto\Desktop\My Web Sites\tucker_and_dales_home_services\.venv\Lib\site-packages\django\template\base.py", line 966, in render_annotated
    return self.render(context)
           ^^^^^^^^^^^^^^^^^^^^
  File "C:\Users\paxto\Desktop\My Web Sites\tucker_and_dales_home_services\.venv\Lib\site-packages\django\template\loader_tags.py", line 132, in render
    compiled_parent = self.get_parent(context)
                      ^^^^^^^^^^^^^^^^^^^^^^^^
  File "C:\Users\paxto\Desktop\My Web Sites\tucker_and_dales_home_services\.venv\Lib\site-packages\django\template\loader_tags.py", line 129, in get_parent
    return self.find_template(parent, context)
           ^^^^^^^^^^^^^^^^^^^^^^^^^^^^^^^^^^^
  File "C:\Users\paxto\Desktop\My Web Sites\tucker_and_dales_home_services\.venv\Lib\site-packages\django\template\loader_tags.py", line 107, in find_template
    template, origin = context.template.engine.find_template(
                       ^^^^^^^^^^^^^^^^^^^^^^^^^^^^^^^^^^^^^^
  File "C:\Users\paxto\Desktop\My Web Sites\tucker_and_dales_home_services\.venv\Lib\site-packages\django\template\engine.py", line 161, in find_template
    raise TemplateDoesNotExist(name, tried=tried)
django.template.exceptions.TemplateDoesNotExist: core/base.html

The above exception was the direct cause of the following exception:

Traceback (most recent call last):
  File "C:\Users\paxto\Desktop\My Web Sites\tucker_and_dales_home_services\.venv\Lib\site-packages\django\core\handlers\exception.py", line 55, in inner
    response = get_response(request)
               ^^^^^^^^^^^^^^^^^^^^^
  File "C:\Users\paxto\Desktop\My Web Sites\tucker_and_dales_home_services\.venv\Lib\site-packages\django\core\handlers\base.py", line 197, in _get_response
    response = wrapped_callback(request, *callback_args, **callback_kwargs)
               ^^^^^^^^^^^^^^^^^^^^^^^^^^^^^^^^^^^^^^^^^^^^^^^^^^^^^^^^^^^^
  File "C:\Users\paxto\Desktop\My Web Sites\tucker_and_dales_home_services\core\views.py", line 10, in home
    return render(request, "core/home.html")
           ^^^^^^^^^^^^^^^^^^^^^^^^^^^^^^^^^
  File "C:\Users\paxto\Desktop\My Web Sites\tucker_and_dales_home_services\.venv\Lib\site-packages\django\shortcuts.py", line 24, in render
    content = loader.render_to_string(template_name, context, request, using=using)
              ^^^^^^^^^^^^^^^^^^^^^^^^^^^^^^^^^^^^^^^^^^^^^^^^^^^^^^^^^^^^^^^^^^^^^
  File "C:\Users\paxto\Desktop\My Web Sites\tucker_and_dales_home_services\.venv\Lib\site-packages\django\template\loader.py", line 62, in render_to_string
    return template.render(context, request)
           ^^^^^^^^^^^^^^^^^^^^^^^^^^^^^^^^^
  File "C:\Users\paxto\Desktop\My Web Sites\tucker_and_dales_home_services\.venv\Lib\site-packages\django\template\backends\django.py", line 63, in render
    reraise(exc, self.backend)
  File "C:\Users\paxto\Desktop\My Web Sites\tucker_and_dales_home_services\.venv\Lib\site-packages\django\template\backends\django.py", line 84, in reraise
    raise new from exc
django.template.exceptions.TemplateDoesNotExist: core/base.html
[2025-09-21 21:24:34,166] ERROR django.server "GET / HTTP/1.1" 500 132846
[2025-09-21 21:45:25,177] ERROR django.request Internal Server Error: /customers/
Traceback (most recent call last):
  File "C:\Users\paxto\Desktop\My Web Sites\tucker_and_dales_ho[2025-09-21 21:36:31,942] ERROR django.request Internal Server Error: /
Traceback (most recent call last):
  File "C:\Users\paxto\Desktop\My Web Sites\tucker_and_dales_home_services\.venv\Lib\site-packages\django\template\backends\django.py", line 61, in render
    return self.template.render(context)
           ^^^^^^^^^^^^^^^^^^^^^^^^^^^^^
  File "C:\Users\paxto\Desktop\My Web Sites\tucker_and_dales_home_services\.venv\Lib\site-packages\django\template\base.py", line 175, in render
    return self._render(context)
           ^^^^^^^^^^^^^^^^^^^^^
  File "C:\Users\paxto\Desktop\My Web Sites\tucker_and_dales_home_services\.venv\Lib\site-packages\django\template\base.py", line 167, in _render
    return self.nodelist.render(context)
           ^^^^^^^^^^^^^^^^^^^^^^^^^^^^^
  File "C:\Users\paxto\Desktop\My Web Sites\tucker_and_dales_home_services\.venv\Lib\site-packages\django\template\base.py", line 1005, in render
    return SafeString("".join([node.render_annotated(context) for node in self]))
                               ^^^^^^^^^^^^^^^^^^^^^^^^^^^^^^
  File "C:\Users\paxto\Desktop\My Web Sites\tucker_and_dales_home_services\.venv\Lib\site-packages\django\template\base.py", line 966, in render_annotated
    return self.render(context)
           ^^^^^^^^^^^^^^^^^^^^
  File "C:\Users\paxto\Desktop\My Web Sites\tucker_and_dales_home_services\.venv\Lib\site-packages\django\template\loader_tags.py", line 132, in render
    compiled_parent = self.get_parent(context)
                      ^^^^^^^^^^^^^^^^^^^^^^^^
  File "C:\Users\paxto\Desktop\My Web Sites\tucker_and_dales_home_services\.venv\Lib\site-packages\django\template\loader_tags.py", line 129, in get_parent
    return self.find_template(parent, context)
           ^^^^^^^^^^^^^^^^^^^^^^^^^^^^^^^^^^^
  File "C:\Users\paxto\Desktop\My Web Sites\tucker_and_dales_home_services\.venv\Lib\site-packages\django\template\loader_tags.py", line 107, in find_template
    template, origin = context.template.engine.find_template(
                       ^^^^^^^^^^^^^^^^^^^^^^^^^^^^^^^^^^^^^^
  File "C:\Users\paxto\Desktop\My Web Sites\tucker_and_dales_home_services\.venv\Lib\site-packages\django\template\engine.py", line 161, in find_template
    raise TemplateDoesNotExist(name, tried=tried)
django.template.exceptions.TemplateDoesNotExist: core/base.html

The above exception was the direct cause of the following exception:

Traceback (most recent call last):
  File "C:\Users\paxto\Desktop\My Web Sites\tucker_and_dales_home_services\.venv\Lib\site-packages\django\core\handlers\exception.py", line 55, in inner
    response = get_response(request)
               ^^^^^^^^^^^^^^^^^^^^^
  File "C:\Users\paxto\Desktop\My Web Sites\tucker_and_dales_home_services\.venv\Lib\site-packages\django\core\handlers\base.py", line 197, in _get_response
    response = wrapped_callback(request, *callback_args, **callback_kwargs)
               ^^^^^^^^^^^^^^^^^^^^^^^^^^^^^^^^^^^^^^^^^^^^^^^^^^^^^^^^^^^^
  File "C:\Users\paxto\Desktop\My Web Sites\tucker_and_dales_home_services\core\views.py", line 10, in home
    return render(request, "core/home.html")
           ^^^^^^^^^^^^^^^^^^^^^^^^^^^^^^^^^
  File "C:\Users\paxto\Desktop\My Web Sites\tucker_and_dales_home_services\.venv\Lib\site-packages\django\shortcuts.py", line 24, in render
    content = loader.render_to_string(template_name, context, request, using=using)
              ^^^^^^^^^^^^^^^^^^^^^^^^^^^^^^^^^^^^^^^^^^^^^^^^^^^^^^^^^^^^^^^^^^^^^
  File "C:\Users\paxto\Desktop\My Web Sites\tucker_and_dales_home_services\.venv\Lib\site-packages\django\template\loader.py", line 62, in render_to_string
    return template.render(context, request)
           ^^^^^^^^^^^^^^^^^^^^^^^^^^^^^^^^^
  File "C:\Users\paxto\Desktop\My Web Sites\tucker_and_dales_home_services\.venv\Lib\site-packages\django\template\backends\django.py", line 63, in render
    reraise(exc, self.backend)
  File "C:\Users\paxto\Desktop\My Web Sites\tucker_and_dales_home_services\.venv\Lib\site-packages\django\template\backends\django.py", line 84, in reraise
    raise new from exc
django.template.exceptions.TemplateDoesNotExist: core/base.html
[2025-09-21 21:36:31,948] ERROR django.server "GET / HTTP/1.1" 500 132846
[2025-09-21 21:36:34,228] ERROR django.request Internal Server Error: /
Traceback (most recent call last):
  File "C:\Users\paxto\Desktop\My Web Sites\tucker_and_dales_home_services\.venv\Lib\site-packages\django\template\backends\django.py", line 61, in render
    return self.template.render(context)
           ^^^^^^^^^^^^^^^^^^^^^^^^^^^^^
  File "C:\Users\paxto\Desktop\My Web Sites\tucker_and_dales_home_services\.venv\Lib\site-packages\django\template\base.py", line 175, in render
    return self._render(context)
           ^^^^^^^^^^^^^^^^^^^^^
  File "C:\Users\paxto\Desktop\My Web Sites\tucker_and_dales_home_services\.venv\Lib\site-packages\django\template\base.py", line 167, in _render
    return self.nodelist.render(context)
           ^^^^^^^^^^^^^^^^^^^^^^^^^^^^^
  File "C:\Users\paxto\Desktop\My Web Sites\tucker_and_dales_home_services\.venv\Lib\site-packages\django\template\base.py", line 1005, in render
    return SafeString("".join([node.render_annotated(context) for node in self]))
                               ^^^^^^^^^^^^^^^^^^^^^^^^^^^^^^
  File "C:\Users\paxto\Desktop\My Web Sites\tucker_and_dales_home_services\.venv\Lib\site-packages\django\template\base.py", line 966, in render_annotated
    return self.render(context)
           ^^^^^^^^^^^^^^^^^^^^
  File "C:\Users\paxto\Desktop\My Web Sites\tucker_and_dales_home_services\.venv\Lib\site-packages\django\template\loader_tags.py", line 132, in render
    compiled_parent = self.get_parent(context)
                      ^^^^^^^^^^^^^^^^^^^^^^^^
  File "C:\Users\paxto\Desktop\My Web Sites\tucker_and_dales_home_services\.venv\Lib\site-packages\django\template\loader_tags.py", line 129, in get_parent
    return self.find_template(parent, context)
           ^^^^^^^^^^^^^^^^^^^^^^^^^^^^^^^^^^^
  File "C:\Users\paxto\Desktop\My Web Sites\tucker_and_dales_home_services\.venv\Lib\site-packages\django\template\loader_tags.py", line 107, in find_template
    template, origin = context.template.engine.find_template(
                       ^^^^^^^^^^^^^^^^^^^^^^^^^^^^^^^^^^^^^^
  File "C:\Users\paxto\Desktop\My Web Sites\tucker_and_dales_home_services\.venv\Lib\site-packages\django\template\engine.py", line 161, in find_template
    raise TemplateDoesNotExist(name, tried=tried)
django.template.exceptions.TemplateDoesNotExist: core/base.html

The above exception was the direct cause of the following exception:

Traceback (most recent call last):
  File "C:\Users\paxto\Desktop\My Web Sites\tucker_and_dales_home_services\.venv\Lib\site-packages\django\core\handlers\exception.py", line 55, in inner
    response = get_response(request)
               ^^^^^^^^^^^^^^^^^^^^^
  File "C:\Users\paxto\Desktop\My Web Sites\tucker_and_dales_home_services\.venv\Lib\site-packages\django\core\handlers\base.py", line 197, in _get_response
    response = wrapped_callback(request, *callback_args, **callback_kwargs)
               ^^^^^^^^^^^^^^^^^^^^^^^^^^^^^^^^^^^^^^^^^^^^^^^^^^^^^^^^^^^^
  File "C:\Users\paxto\Desktop\My Web Sites\tucker_and_dales_home_services\core\views.py", line 10, in home
    return render(request, "core/home.html")
           ^^^^^^^^^^^^^^^^^^^^^^^^^^^^^^^^^
  File "C:\Users\paxto\Desktop\My Web Sites\tucker_and_dales_home_services\.venv\Lib\site-packages\django\shortcuts.py", line 24, in render
    content = loader.render_to_string(template_name, context, request, using=using)
              ^^^^^^^^^^^^^^^^^^^^^^^^^^^^^^^^^^^^^^^^^^^^^^^^^^^^^^^^^^^^^^^^^^^^^
  File "C:\Users\paxto\Desktop\My Web Sites\tucker_and_dales_home_services\.venv\Lib\site-packages\django\template\loader.py", line 62, in render_to_string
    return template.render(context, request)
           ^^^^^^^^^^^^^^^^^^^^^^^^^^^^^^^^^
  File "C:\Users\paxto\Desktop\My Web Sites\tucker_and_dales_home_services\.venv\Lib\site-packages\django\template\backends\django.py", line 63, in render
    reraise(exc, self.backend)
  File "C:\Users\paxto\Desktop\My Web Sites\tucker_and_dales_home_services\.venv\Lib\site-packages\django\template\backends\django.py", line 84, in reraise
    raise new from exc
django.template.exceptions.TemplateDoesNotExist: core/base.html
[2025-09-21 21:36:34,233] ERROR django.server "GET / HTTP/1.1" 500 132983
[2025-09-21 21:36:37,001] ERROR django.request Internal Server Error: /
Traceback (most recent call last):
  File "C:\Users\paxto\Desktop\My Web Sites\tucker_and_dales_home_services\.venv\Lib\site-packages\django\template\backends\django.py", line 61, in render
    return self.template.render(context)
           ^^^^^^^^^^^^^^^^^^^^^^^^^^^^^
  File "C:\Users\paxto\Desktop\My Web Sites\tucker_and_dales_home_services\.venv\Lib\site-packages\django\template\base.py", line 175, in render
    return self._render(context)
           ^^^^^^^^^^^^^^^^^^^^^
  File "C:\Users\paxto\Desktop\My Web Sites\tucker_and_dales_home_services\.venv\Lib\site-packages\django\template\base.py", line 167, in _render
    return self.nodelist.render(context)
           ^^^^^^^^^^^^^^^^^^^^^^^^^^^^^
  File "C:\Users\paxto\Desktop\My Web Sites\tucker_and_dales_home_services\.venv\Lib\site-packages\django\template\base.py", line 1005, in render
    return SafeString("".join([node.render_annotated(context) for node in self]))
                               ^^^^^^^^^^^^^^^^^^^^^^^^^^^^^^
  File "C:\Users\paxto\Desktop\My Web Sites\tucker_and_dales_home_services\.venv\Lib\site-packages\django\template\base.py", line 966, in render_annotated
    return self.render(context)
           ^^^^^^^^^^^^^^^^^^^^
  File "C:\Users\paxto\Desktop\My Web Sites\tucker_and_dales_home_services\.venv\Lib\site-packages\django\template\loader_tags.py", line 132, in render
    compiled_parent = self.get_parent(context)
                      ^^^^^^^^^^^^^^^^^^^^^^^^
  File "C:\Users\paxto\Desktop\My Web Sites\tucker_and_dales_home_services\.venv\Lib\site-packages\django\template\loader_tags.py", line 129, in get_parent
    return self.find_template(parent, context)
           ^^^^^^^^^^^^^^^^^^^^^^^^^^^^^^^^^^^
  File "C:\Users\paxto\Desktop\My Web Sites\tucker_and_dales_home_services\.venv\Lib\site-packages\django\template\loader_tags.py", line 107, in find_template
    template, origin = context.template.engine.find_template(
                       ^^^^^^^^^^^^^^^^^^^^^^^^^^^^^^^^^^^^^^
  File "C:\Users\paxto\Desktop\My Web Sites\tucker_and_dales_home_services\.venv\Lib\site-packages\django\template\engine.py", line 161, in find_template
    raise TemplateDoesNotExist(name, tried=tried)
django.template.exceptions.TemplateDoesNotExist: core/base.html

The above exception was the direct cause of the following exception:

Traceback (most recent call last):
  File "C:\Users\paxto\Desktop\My Web Sites\tucker_and_dales_home_services\.venv\Lib\site-packages\django\core\handlers\exception.py", line 55, in inner
    response = get_response(request)
               ^^^^^^^^^^^^^^^^^^^^^
  File "C:\Users\paxto\Desktop\My Web Sites\tucker_and_dales_home_services\.venv\Lib\site-packages\django\core\handlers\base.py", line 197, in _get_response
    response = wrapped_callback(request, *callback_args, **callback_kwargs)
               ^^^^^^^^^^^^^^^^^^^^^^^^^^^^^^^^^^^^^^^^^^^^^^^^^^^^^^^^^^^^
  File "C:\Users\paxto\Desktop\My Web Sites\tucker_and_dales_home_services\core\views.py", line 10, in home
    return render(request, "core/home.html")
           ^^^^^^^^^^^^^^^^^^^^^^^^^^^^^^^^^
  File "C:\Users\paxto\Desktop\My Web Sites\tucker_and_dales_home_services\.venv\Lib\site-packages\django\shortcuts.py", line 24, in render
    content = loader.render_to_string(template_name, context, request, using=using)
              ^^^^^^^^^^^^^^^^^^^^^^^^^^^^^^^^^^^^^^^^^^^^^^^^^^^^^^^^^^^^^^^^^^^^^
  File "C:\Users\paxto\Desktop\My Web Sites\tucker_and_dales_home_services\.venv\Lib\site-packages\django\template\loader.py", line 62, in render_to_string
    return template.render(context, request)
           ^^^^^^^^^^^^^^^^^^^^^^^^^^^^^^^^^
  File "C:\Users\paxto\Desktop\My Web Sites\tucker_and_dales_home_services\.venv\Lib\site-packages\django\template\backends\django.py", line 63, in render
    reraise(exc, self.backend)
  File "C:\Users\paxto\Desktop\My Web Sites\tucker_and_dales_home_services\.venv\Lib\site-packages\django\template\backends\django.py", line 84, in reraise
    raise new from exc
django.template.exceptions.TemplateDoesNotExist: core/base.html
[2025-09-21 21:36:37,005] ERROR django.server "GET / HTTP/1.1" 500 133111
me_services\.venv\Lib\site-packages\django\core\handlers\exception.py", line 55, in inner
    response = get_response(request)
               ^^^^^^^^^^^^^^^^^^^^^
  File "C:\Users\paxto\Desktop\My Web Sites\tucker_and_dales_home_services\.venv\Lib\site-packages\django\core\handlers\base.py", line 197, in _get_response
    response = wrapped_callback(request, *callback_args, **callback_kwargs)
               ^^^^^^^^^^^^^^^^^^^^^^^^^^^^^^^^^^^^^^^^^^^^^^^^^^^^^^^^^^^^
  File "C:\Users\paxto\Desktop\My Web Sites\tucker_and_dales_home_services\customers\views.py", line 29, in customer_list
    return render(
           ^^^^^^^
  File "C:\Users\paxto\Desktop\My Web Sites\tucker_and_dales_home_services\.venv\Lib\site-packages\django\shortcuts.py", line 24, in render
    content = loader.render_to_string(template_name, context, request, using=using)
              ^^^^^^^^^^^^^^^^^^^^^^^^^^^^^^^^^^^^^^^^^^^^^^^^^^^^^^^^^^^^^^^^^^^^^
  File "C:\Users\paxto\Desktop\My Web Sites\tucker_and_dales_home_services\.venv\Lib\site-packages\django\template\loader.py", line 61, in render_to_string
    template = get_template(template_name, using=using)
               ^^^^^^^^^^^^^^^^^^^^^^^^^^^^^^^^^^^^^^^^
  File "C:\Users\paxto\Desktop\My Web Sites\tucker_and_dales_home_services\.venv\Lib\site-packages\django\template\loader.py", line 15, in get_template
    return engine.get_template(template_name)
           ^^^^^^^^^^^^^^^^^^^^^^^^^^^^^^^^^^
  File "C:\Users\paxto\Desktop\My Web Sites\tucker_and_dales_home_services\.venv\Lib\site-packages\django\template\backends\django.py", line 33, in get_template
    return Template(self.engine.get_template(template_name), self)
                    ^^^^^^^^^^^^^^^^^^^^^^^^^^^^^^^^^^^^^^^
  File "C:\Users\paxto\Desktop\My Web Sites\tucker_and_dales_home_services\.venv\Lib\site-packages\django\template\engine.py", line 175, in get_template
    template, origin = self.find_template(template_name)
                       ^^^^^^^^^^^^^^^^^^^^^^^^^^^^^^^^^
  File "C:\Users\paxto\Desktop\My Web Sites\tucker_and_dales_home_services\.venv\Lib\site-packages\django\template\engine.py", line 157, in find_template
    template = loader.get_template(name, skip=skip)
               ^^^^^^^^^^^^^^^^^^^^^^^^^^^^^^^^^^^^
  File "C:\Users\paxto\Desktop\My Web Sites\tucker_and_dales_home_services\.venv\Lib\site-packages\django\template\loaders\cached.py", line 57, in get_template
    template = super().get_template(template_name, skip)
               ^^^^^^^^^^^^^^^^^^^^^^^^^^^^^^^^^^^^^^^^^
  File "C:\Users\paxto\Desktop\My Web Sites\tucker_and_dales_home_services\.venv\Lib\site-packages\django\template\loaders\base.py", line 28, in get_template
    return Template(
           ^^^^^^^^^
  File "C:\Users\paxto\Desktop\My Web Sites\tucker_and_dales_home_services\.venv\Lib\site-packages\django\template\base.py", line 154, in __init__
    self.nodelist = self.compile_nodelist()
                    ^^^^^^^^^^^^^^^^^^^^^^^
  File "C:\Users\paxto\Desktop\My Web Sites\tucker_and_dales_home_services\.venv\Lib\site-packages\django\template\base.py", line 200, in compile_nodelist
    return parser.parse()
           ^^^^^^^^^^^^^^
  File "C:\Users\paxto\Desktop\My Web Sites\tucker_and_dales_home_services\.venv\Lib\site-packages\django\template\base.py", line 513, in parse
    raise self.error(token, e)
  File "C:\Users\paxto\Desktop\My Web Sites\tucker_and_dales_home_services\.venv\Lib\site-packages\django\template\base.py", line 511, in parse
    compiled_result = compile_func(self, token)
                      ^^^^^^^^^^^^^^^^^^^^^^^^^
  File "C:\Users\paxto\Desktop\My Web Sites\tucker_and_dales_home_services\.venv\Lib\site-packages\django\template\loader_tags.py", line 293, in do_extends
    nodelist = parser.parse()
               ^^^^^^^^^^^^^^
  File "C:\Users\paxto\Desktop\My Web Sites\tucker_and_dales_home_services\.venv\Lib\site-packages\django\template\base.py", line 513, in parse
    raise self.error(token, e)
  File "C:\Users\paxto\Desktop\My Web Sites\tucker_and_dales_home_services\.venv\Lib\site-packages\django\template\base.py", line 511, in parse
    compiled_result = compile_func(self, token)
                      ^^^^^^^^^^^^^^^^^^^^^^^^^
  File "C:\Users\paxto\Desktop\My Web Sites\tucker_and_dales_home_services\.venv\Lib\site-packages\django\template\loader_tags.py", line 226, in do_block
    raise TemplateSyntaxError(
django.template.exceptions.TemplateSyntaxError: 'block' tag with name 'content' appears more than once
[2025-09-21 21:45:25,183] ERROR django.server "GET /customers/ HTTP/1.1" 500 184486
